<?xml version="1.0" encoding="UTF-8"?>
<!-- Generated by org.testng.reporters.JUnitXMLReporter -->
<testsuite hostname="DESKTOP-DTAJN93" failures="1" tests="11" name="Spentra" time="242.155" errors="0" timestamp="8 Feb 2021 08:36:07 GMT">
  <testcase classname="com.functional.tests.Login" name="negativeLoginTest" time="11.681"/>
  <testcase classname="com.functional.tests.Login" name="negativeLoginTest" time="12.997"/>
  <testcase classname="com.functional.tests.Login" name="negativeLoginTest" time="11.218"/>
  <testcase classname="com.functional.tests.Login" name="negativeLoginTest" time="13.021"/>
  <testcase classname="com.functional.tests.Login" name="logintoApplication" time="17.606"/>
  <testcase classname="com.functional.tests.AddEmp" name="navigateToAddEmployee" time="16.214"/>
  <testcase classname="com.functional.tests.AddEmp" name="addEmployeeDetails" time="39.642">
    <failure type="java.lang.AssertionError" message="expected [This Mobile Number is already in use.] but found [Employee added successfully.]">
      <![CDATA[java.lang.AssertionError: expected [This Mobile Number is already in use.] but found [Employee added successfully.]
	at com.pages.AddEmpPage.verifyMessage(AddEmpPage.java:173)
	at com.functional.tests.AddEmp.addEmployeeDetails(AddEmp.java:29)
	at com.framework.Setup.executeTest(Setup.java:39)
	at com.framework.Start.main(Start.java:23)
... Removed 26 stack frames]]>
    </failure>
  </testcase> <!-- addEmployeeDetails -->
  <testcase classname="com.functional.tests.AddEmp" name="addEmployeeDetails" time="30.519"/>
  <testcase classname="com.functional.tests.AddEmp" name="addEmployeeDetails" time="25.625"/>
  <testcase classname="com.functional.tests.AddEmp" name="addEmployeeDetails" time="34.439"/>
  <testcase classname="com.functional.tests.AddEmp" name="addEmployeeDetails" time="25.695"/>
</testsuite> <!-- Spentra -->
