<?xml version="1.0" encoding="UTF-8"?>
<!-- Generated by org.testng.reporters.JUnitReportReporter -->
<testsuite hostname="DESKTOP-DTAJN93" failures="0" tests="6" name="com.functional.tests.AddEmp" time="172.134" errors="1" timestamp="8 Feb 2021 08:36:09 GMT">
  <testcase classname="com.functional.tests.AddEmp" name="addEmployeeDetails" time="25.695"/>
  <testcase classname="com.functional.tests.AddEmp" name="navigateToAddEmployee" time="16.214"/>
  <testcase classname="com.functional.tests.AddEmp" name="addEmployeeDetails" time="30.519"/>
  <testcase classname="com.functional.tests.AddEmp" name="addEmployeeDetails" time="39.642">
    <error message="expected [This Mobile Number is already in use.] but found [Employee added successfully.]" type="java.lang.AssertionError">
      <![CDATA[java.lang.AssertionError: expected [This Mobile Number is already in use.] but found [Employee added successfully.]
	at org.testng.Assert.fail(Assert.java:94)
	at org.testng.Assert.failNotEquals(Assert.java:494)
	at org.testng.Assert.assertEquals(Assert.java:123)
	at org.testng.Assert.assertEquals(Assert.java:176)
	at org.testng.Assert.assertEquals(Assert.java:186)
	at com.pages.AddEmpPage.verifyMessage(AddEmpPage.java:173)
	at com.functional.tests.AddEmp.addEmployeeDetails(AddEmp.java:29)
	at java.base/jdk.internal.reflect.NativeMethodAccessorImpl.invoke0(Native Method)
	at java.base/jdk.internal.reflect.NativeMethodAccessorImpl.invoke(NativeMethodAccessorImpl.java:64)
	at java.base/jdk.internal.reflect.DelegatingMethodAccessorImpl.invoke(DelegatingMethodAccessorImpl.java:43)
	at java.base/java.lang.reflect.Method.invoke(Method.java:564)
	at org.testng.internal.MethodInvocationHelper.invokeMethod(MethodInvocationHelper.java:80)
	at org.testng.internal.Invoker.invokeMethod(Invoker.java:714)
	at org.testng.internal.Invoker.invokeTestMethod(Invoker.java:901)
	at org.testng.internal.Invoker.invokeTestMethods(Invoker.java:1231)
	at org.testng.internal.TestMethodWorker.invokeTestMethods(TestMethodWorker.java:127)
	at org.testng.internal.TestMethodWorker.run(TestMethodWorker.java:111)
	at org.testng.TestRunner.privateRun(TestRunner.java:767)
	at org.testng.TestRunner.run(TestRunner.java:617)
	at org.testng.SuiteRunner.runTest(SuiteRunner.java:334)
	at org.testng.SuiteRunner.runSequentially(SuiteRunner.java:329)
	at org.testng.SuiteRunner.privateRun(SuiteRunner.java:291)
	at org.testng.SuiteRunner.run(SuiteRunner.java:240)
	at org.testng.SuiteRunnerWorker.runSuite(SuiteRunnerWorker.java:52)
	at org.testng.SuiteRunnerWorker.run(SuiteRunnerWorker.java:86)
	at org.testng.TestNG.runSuitesSequentially(TestNG.java:1198)
	at org.testng.TestNG.runSuitesLocally(TestNG.java:1123)
	at org.testng.TestNG.run(TestNG.java:1031)
	at com.framework.Setup.executeTest(Setup.java:39)
	at com.framework.Start.main(Start.java:23)
]]>
    </error>
  </testcase> <!-- addEmployeeDetails -->
  <testcase classname="com.functional.tests.AddEmp" name="addEmployeeDetails" time="25.625"/>
  <testcase classname="com.functional.tests.AddEmp" name="addEmployeeDetails" time="34.439"/>
</testsuite> <!-- com.functional.tests.AddEmp -->
